Workbook

Sheet Balance de comprobación
B1: Saldo inicial | D1: De 01/01/2025 a 31/03/2026 | F1: Saldo final
B3: Debe | C3: Haber | D3: Debe | E3: Haber | F3: Debe | G3: Haber | I3: LIBRO MAYOR | J3: DIF
A4: 1211003 FACTURAS POR COBRAR DEL EXTERIOR | D4: 42.58 | E4: 42.58 | I4: 0
A5: 1212001 FACTURAS POR COBRAR NACIONALES M.N. | D5: 80303081 | E5: 76745669 | F5: 3557412.7 | I5: =+'12121xx1'!M2772 -> 3557412.7 | J5: =+F5-I5 -> -8.3819032e-09
A6: 1212002 FACTURAS POR COBRAR NACIONALES M.E. | D6: 294639.07 | E6: 195884.59 | F6: 98754.48 | I6: =+'1212xx2'!M98 -> 98754.48 | J6: =+F6-I6 -> 0
A7: 1212003 FACTURAS POR COBRAR DEL EXTERIOR | D7: 81530992 | E7: 71881450 | F7: 9649541.6 | I7: =+'1212xx3'!M82 -> 9649541.6 | J7: =+F7-I7 -> 0
A8: 1220001 ANTICIPOS CLIENTES NACIONAL M.N. | D8: 857993.19 | E8: 942331.14 | G8: 84337.95 | I8: =+'122xx1'!M99 -> -84337.95 | J8: =+G8+I8 -> 0
A9: 1220002 ANTICIPOS CLIENTES NACIONAL M.E. | D9: 84.59 | E9: 29089.79 | G9: 29005.2 | I9: =+'122xx2'!M5 -> -29005.2 | J9: =+G9+I9 -> 0
A10: 1220003 ANTICIPOS CLIENTES DEL EXTERIOR | D10: 10473235 | E10: 14306947 | G10: 3833712.5 | I10: =+'122xx3'!M130 -> -3833712.5 | J10: =+G10+I10 -> 0
A11: 1220004 ANTICIPOS VENTA DE DEPARTAMENTO PROY SB | D11: 134880.59 | E11: 237348.82 | G11: 102468.23 | I11: =+'122xx4'!M177 -> -102468.23 | J11: =+G11+I11 -> 0
A12: 1220005 ANTICIPOS VENTA - MARKETPLACE | D12: 131066.59 | E12: 189006.87 | G12: 57940.28 | I12: =+'122xx5'!M879 -> -57940.28 | J12: =+G12+I12 -> 0
A13: 1220006 ANTICIPOS VENTAS MN - SALDOS INICIALES | D13: 128978.39 | E13: 128978.39 | I13: 0
A14: 1220007 ANTICIPOS VENTAS ME - SALDOS INICIALES | D14: 1236491.5 | E14: 1236491.5 | I14: 0
A15: 1232001 LETRAS EN CARTERA NACIONAL M.N. | D15: 43581620 | E15: 42326586 | F15: 1255034.3 | I15: =+'1232xx1'!M136 -> 1255034.3 | J15: =+F15-I15 -> 0
A16: 1232002 LETRAS EN CARTERA NACIONAL M.E. | D16: 3956140.9 | E16: 3956140.9 | I16: 0
A17: 1233001 LETRAS EN COBRANZA NACIONAL M.N. | D17: 7623115.6 | E17: 6227841.4 | F17: 1395274.2 | I17: =+'1233xx1'!M98 -> 1395274.2 | J17: =+F17-I17 -> 0
A18: 1234001 LETRAS EN DESCUENTO NACIONAL M.N. | D18: 38471362 | E18: 34251057 | F18: 4220304.4 | I18: =+'1234xx1'!M586 -> 4220304.5 | J18: =+F18-I18 -> -9.3132257e-09
A19: 1234004 LETRAS PROTESTADAS NACIONAL M.N. | D19: 1130525 | E19: 1055020.4 | F19: 75504.64 | I19: =+'1234xx4'!M41 -> 75504.64 | J19: =+F19-I19 -> 0
A20: 1239001 LETRAS - SALDOS INICIALES | D20: 8310858 | E20: 8310858
A21: 1312001 FACTURAS POR COBRAR NACIONALES M.N. - EMITIDAS | D21: 5917509.7 | E21: 4111974.1 | F21: 1806544.5 | I21: =+'1312xx1'!M142 -> 1806544.5 | J21: =+F21-I21 -> 0
A22: 1312002 FACTURAS POR COBRAR NACIONALES M.E. - EMITIDAS | D22: 13118.67 | E22: 11375.67 | F22: 1743 | I22: =+'1312xx2'!M8 -> 1743 | J22: =+F22-I22 -> 0
A23: 1312003 FACTURAS POR COBRAR DEL EXTERIOR - EMITIDAS | D23: 33407134 | E23: 20872452 | F23: 12534682 | I23: =+'1312xx3'!J59 -> 12534682 | J23: =+F23-I23 -> 0.0032599978
A24: 1321001 ANTICIPOS CLIENTES NACIONAL M.N. | D24: 4402.98 | E24: 4481.83 | G24: 78.85 | I24: =+'1321xx1'!M5 -> -78.85 | J24: =+G24+I24 -> 3.6948222e-13
A25: 1321003 ANTICIPOS CLIENTES DEL EXTERIOR | D25: 2909244.9 | E25: 2909244.9
A26: 1331001 LETRAS EN CARTERA NACIONAL M.N. | D26: 12166.48 | F26: 12166.48 | I26: =+'1331xx1'!M11 -> 12166.48 | J26: =+F26-I26 -> 0
A27: 1332001 LETRAS EN COBRANZA NACIONAL M.N. | D27: 3180.62 | F27: 3180.62 | I27: =+'1332xx1'!M14 -> 3180.62 | J27: =+F27-I27 -> 0
A28: 1333004 LETRAS PROTESTADAS NACIONAL M.N. | D28: 73693.8 | F28: 73693.8 | I28: =+'133xx4'!M91 -> 73693.8 | J28: =+F28-I28 -> 0
A29: 1911001 FACTURAS, BOLETAS Y OTROS COMPROBANTES POR COBRAR M.N. | E29: 129937.94 | G29: 129937.94
A30: 1913001 LETRAS POR COBRAR M.N. | E30: 178937.66 | G30: 178937.66
A31: 4511002 RESPONSABILIDAD LETRAS DESCONTADAS MN | D31: 35360332 | E31: 39580637 | G31: 4220304.4

Sheet 12121xx1
A1: Asiento contable | B1: Número | C1: Fecha | D1: Fecha de vencimiento | E1: Cuenta | F1: Socio | G1: Etiqueta | H1: Referencia | I1: Moneda | J1: Importe en moneda | K1: Debe | L1: Haber | M1: Saldo | N1: Conciliación | O1: Creado por
A2: 1212001 FACTURAS POR COBRAR NACIONALES M.N. (29740)
A3: F F01-00005209 | B3: F F01-00005209 | C3: 46112 | D3: 46142 | E3: 1212001 FACTURAS POR COBRAR NACIONALES M.N. | F3: VETERINARIAS INTEGRADAS S.A.C. | G3: F F01-00005209 | I3: PEN | J3: 1318.06 | K3: 1318.06 | M3: 1318.06 | O3: PALIZA CAMAVILCA, JHOSSELYN JARUMY
A4: F F01-00005208 | B4: F F01-00005208 | C4: 46112 | D4: 46142 | E4: 1212001 FACTURAS POR COBRAR NACIONALES M.N. | F4: VETERINARIAS INTEGRADAS S.A.C. | G4: F F01-00005208 | I4: PEN | J4: 988.84 | K4: 988.84 | M4: 988.84 | O4: PALIZA CAMAVILCA, JHOSSELYN JARUMY
A5: F F01-00005207 | B5: F F01-00005207 | C5: 46112 | D5: 46142 | E5: 1212001 FACTURAS POR COBRAR NACIONALES M.N. | F5: SOLUCIONES Y DESARROLLO VETERINARIO SOCIEDAD ANONIMA CERRADA | G5: F F01-00005207 | I5: PEN | J5: 610.65 | K5: 610.65 | M5: 610.65 | N5: A156993 | O5: PALIZA CAMAVILCA, JHOSSELYN JARUMY
A6: F F01-00005206 | B6: F F01-00005206 | C6: 46112 | D6: 46142 | E6: 1212001 FACTURAS POR COBRAR NACIONALES M.N. | F6: MASCOTAS PERUANAS S.A.C. | G6: F F01-00005206 | I6: PEN | J6: 3149.35 | K6: 3149.35 | M6: 3149.35 | N6: A150553 | O6: PALIZA CAMAVILCA, JHOSSELYN JARUMY
A7: F F01-00005203 | B7: F F01-00005203 | C7: 46112 | D7: 46202 | E7: 1212001 FACTURAS POR COBRAR NACIONALES M.N. | F7: TIENDAS SUPERPET SOCIEDAD ANONIMA CERRADA - TIENDAS SUPERPET S.A.C. | G7: F F01-00005203 | I7: PEN | J7: 14876.89 | K7: 14876.89 | M7: 14876.89 | O7: PALIZA CAMAVILCA, JHOSSELYN JARUMY
A8: F F01-00005198 | B8: F F01-00005198 | C8: 46112 | D8: 46142 | E8: 1212001 FACTURAS POR COBRAR NACIONALES M.N. | F8: M & C VET S.A.C. | G8: F F01-00005198 | I8: PEN | J8: 1749.35 | K8: 1749.35 | M8: 1749.35 | N8: A149116 | O8: PALIZA CAMAVILCA, JHOSSELYN JARUMY
A9: F F01-00005193 | B9: F F01-00005193 | C9: 46112 | D9: 46172 | E9: 1212001 FACTURAS POR COBRAR NACIONALES M.N. | F9: REPRESENTACIONES DURAND S.A.C. | G9: F F01-00005193 | I9: PEN | J9: 3707.09 | K9: 3707.09 | M9: 3707.09 | N9: A145572 | O9: PALIZA CAMAVILCA, JHOSSELYN JARUMY
A10: F F01-00005187 | B10: F F01-00005187 | C10: 46112 | D10: 46112 | E10: 1212001 FACTURAS POR COBRAR NACIONALES M.N. | F10: TAI LOY S.A. | G10: F F01-00005187 | I10: PEN | J10: 71.91 | K10: 71.91 | M10: 71.91 | O10: PALIZA CAMAVILCA, JHOSSELYN JARUMY
A11: F F01-00005179 | B11: F F01-00005179 | C11: 46112 | D11: 46112 | E11: 1212001 FACTURAS POR COBRAR NACIONALES M.N. | F11: TAI LOY S.A. | G11: F F01-00005179 | I11: PEN | J11: 180.2 | K11: 180.2 | M11: 180.2 | O11: PALIZA CAMAVILCA, JHOSSELYN JARUMY
A12: F F01-00005175 | B12: F F01-00005175 | C12: 46112 | D12: 46112 | E12: 1212001 FACTURAS POR COBRAR NACIONALES M.N. | F12: GARCIA FIESTAS JOSE AURELIO-10105455629 | G12: F F01-00005175 | I12: PEN | J12: 860 | K12: 860 | M12: 860 | N12: A148148 | O12: PALIZA CAMAVILCA, JHOSSELYN JARUMY
A13: F F01-00005174 | B13: F F01-00005174 | C13: 46112 | D13: 46112 | E13: 1212001 FACTURAS POR COBRAR NACIONALES M.N. | F13: TAI LOY S.A. | G13: F F01-00005174 | I13: PEN | J13: 48.96 | K13: 48.96 | M13: 48.96 | O13: PALIZA CAMAVILCA, JHOSSELYN JARUMY
A14: F D01-00000263 | B14: F D01-00000263 | C14: 46112 | D14: 46112 | E14: 1212001 FACTURAS POR COBRAR NACIONALES M.N. | F14: LESCANO VALENCIA AMANDA ANGELICA | G14: F D01-00000263 | I14: PEN | J14: 100.92 | K14: 100.92 | M14: 100.92 | O14: MATTO ASTETE, AUGUSTO WALTER
A15: CAMBI/2026/03/1731 (AJUSTE POR DIFERENCIA DE CAMBIO MAR-2026) | B15: CAMBI/2026/03/1731 | C15: 46112 | E15: 1212001 FACTURAS POR COBRAR NACIONALES M.N. | G15: AJUSTE DF TC MAR-2026 | H15: AJUSTE POR DIFERENCIA DE CAMBIO MAR-2026 | I15: USD | K15: 8.9 | M15: 8.9 | N15: A159652 | O15: BACKOFIS
A16: B B01-00007574 | B16: B B01-00007574 | C16: 46112 | D16: 46112 | E16: 1212001 FACTURAS POR COBRAR NACIONALES M.N. | F16: PEDEMONTE CORDOVA, HILDE ALBERTH | G16: B B01-00007574 | I16: PEN | J16: 132.99 | K16: 132.99 | M16: 132.99 | N16: A158708 | O16: PALIZA CAMAVILCA, JHOSSELYN JARUMY
A17: B B01-00007573 | B17: B B01-00007573 | C17: 46112 | D17: 46112 | E17: 1212001 FACTURAS POR COBRAR NACIONALES M.N. | F17: ALMEYDA CANDIOTI, KEVIN ALEXANDER | G17: B B01-00007573 | I17: PEN | J17: 162.41 | K17: 162.41 | M17: 162.41 | N17: A158709 | O17: PALIZA CAMAVILCA, JHOSSELYN JARUMY
A18: B B01-00007572 | B18: B B01-00007572 | C18: 46112 | D18: 46112 | E18: 1212001 FACTURAS POR COBRAR NACIONALES M.N. | F18: GUZMAN DOMINGUEZ, PEDRO ARTURO | G18: B B01-00007572 | I18: PEN | J18: 279.17 | K18: 279.17 | M18: 279.17 | N18: A158710 | O18: PALIZA CAMAVILCA, JHOSSELYN JARUMY
A19: B B01-00007569 | B19: B B01-00007569 | C19: 46112 | D19: 46112 | E19: 1212001 FACTURAS POR COBRAR NACIONALES M.N. | F19: RAMIREZ CORDOVA, NELLY JUANITA | G19: B B01-00007569 | I19: PEN | J19: 229.5 | K19: 229.5 | M19: 229.5 | O19: PALIZA CAMAVILCA, JHOSSELYN JARUMY
A20: B B01-00007568 | B20: B B01-00007568 | C20: 46112 | D20: 46112 | E20: 1212001 FACTURAS POR COBRAR NACIONALES M.N. | F20: PILCO GOMEZ, LARISA VICTORIA | G20: B B01-00007568 | I20: PEN | J20: 561.68 | K20: 561.68 | M20: 561.68 | N20: A158711 | O20: PALIZA CAMAVILCA, JHOSSELYN JARUMY
A21: B B01-00007566 | B21: B B01-00007566 | C21: 46112 | D21: 46112 | E21: 1212001 FACTURAS POR COBRAR NACIONALES M.N. | F21: CUADROS LUTTERBACH, DIETLIND KAREN | G21: B B01-00007566 | I21: PEN | J21: 88.31 | K21: 88.31 | M21: 88.31 | N21: A158712 | O21: PALIZA CAMAVILCA, JHOSSELYN JARUMY
A22: F F01-00005170 | B22: F F01-00005170 | C22: 46111 | D22: 46186 | E22: 1212001 FACTURAS POR COBRAR NACIONALES M.N. | F22: TOP VETERINARIA S.A.C. | G22: F F01-00005170 | I22: PEN | J22: 147833.88 | K22: 147833.88 | M22: 147833.88 | N22: A148597 | O22: PALIZA CAMAVILCA, JHOSSELYN JARUMY
A23: F F01-00005168 | B23: F F01-00005168 | C23: 46111 | D23: 46201 | E23: 1212001 FACTURAS POR COBRAR NACIONALES M.N. | F23: AGROPEC SOCIEDAD COMERCIAL DE RESPONSABILIDAD LIMITADA | G23: F F01-00005168 | I23: PEN | J23: 12845.51 | K23: 12845.51 | M23: 12845.51 | N23: A144559 | O23: PALIZA CAMAVILCA, JHOSSELYN JARUMY
A24: F F01-00005167 | B24: F F01-00005167 | C24: 46111 | D24: 46201 | E24: 1212001 FACTURAS POR COBRAR NACIONALES M.N. | F24: TIENDAS SUPERPET SOCIEDAD ANONIMA CERRADA - TIENDAS SUPERPET S.A.C. | G24: F F01-00005167 | I24: PEN | J24: 31865.51 | K24: 31865.51 | M24: 31865.51 | O24: PALIZA CAMAVILCA, JHOSSELYN JARUMY
A25: F F01-00005162 | B25: F F01-00005162 | C25: 46111 | D25: 46171 | E25: 1212001 FACTURAS POR COBRAR NACIONALES M.N. | F25: DISTRIBUCIONES AGROVENS E.I.R.L. | G25: F F01-00005162 | I25: PEN | J25: 3071.33 | K25: 3071.33 | M25: 3071.33 | N25: A144205 | O25: PALIZA CAMAVILCA, JHOSSELYN JARUMY
A26: F F01-00005157 | B26: F F01-00005157 | C26: 46111 | D26: 46141 | E26: 1212001 FACTURAS POR COBRAR NACIONALES M.N. | F26: GROUP VET S.A.C. | G26: F F01-00005157 | I26: PEN | J26: 2582.78 | K26: 2582.78 | M26: 2582.78 | N26: A153156 | O26: PALIZA CAMAVILCA, JHOSSELYN JARUMY
A27: F F01-00005151 | B27: F F01-00005151 | C27: 46111 | D27: 46111 | E27: 1212001 FACTURAS POR COBRAR NACIONALES M.N. | F27: TAI LOY S.A. | G27: F F01-00005151 | I27: PEN | J27: 36.72 | K27: 36.72 | M27: 36.72 | O27: PALIZA CAMAVILCA, JHOSSELYN JARUMY
A28: F F01-00005148 | B28: F F01-00005148 | C28: 46111 | D28: 46111 | E28: 1212001 FACTURAS POR COBRAR NACIONALES M.N. | F28: LSPSICOTERAPIA E.I.R.L. | G28: F F01-00005148 | I28: PEN | J28: 131.04 | K28: 131.04 | M28: 131.04 | N28: A158696 | O28: PALIZA CAMAVILCA, JHOSSELYN JARUMY
A29: F F01-00005144 | B29: F F01-00005144 | C29: 46111 | D29: 46111 | E29: 1212001 FACTURAS POR COBRAR NACIONALES M.N. | F29: TAI LOY S.A. | G29: F F01-00005144 | I29: PEN | J29: 180.2 | K29: 180.2 | M29: 180.2 | O29: PALIZA CAMAVILCA, JHOSSELYN JARUMY
A30: F D01-00000262 | B30: F D01-00000262 | C30: 46111 | D30: 46111 | E30: 1212001 FACTURAS POR COBRAR NACIONALES M.N. | F30: H & P DISTRIBUCIONES Y REPRESENTACIONES SOCIEDAD ANONIMA CERRADA | G30: F D01-00000262 | I30: PEN | J30: 168.48 | K30: 168.48 | M30: 168.48 | N30: A158008 | O30: PALIZA CAMAVILCA, JHOSSELYN JARUMY
A31: B B01-00007557 | B31: B B01-00007557 | C31: 46111 | D31: 46111 | E31: 1212001 FACTURAS POR COBRAR NACIONALES M.N. | F31: ESPINOZA MELENDEZ, FRIDA SOFIA | G31: B B01-00007557 | I31: PEN | J31: 188.2 | K31: 188.2 | M31: 188.2 | N31: A158697 | O31: PALIZA CAMAVILCA, JHOSSELYN JARUMY
A32: B B01-00007536 | B32: B B01-00007536 | C32: 46111 | D32: 46111 | E32: 1212001 FACTURAS POR COBRAR NACIONALES M.N. | F32: BRACAMONTE FERNANDEZ, LUIS FERNANDO | G32: B B01-00007536 | I32: PEN | J32: 146.25 | K32: 146.25 | M32: 146.25 | N32: A159010 | O32: PALIZA CAMAVILCA, JHOSSELYN JARUMY
A33: B B01-00007528 | B33: B B01-00007528 | C33: 46111 | D33: 46111 | E33: 1212001 FACTURAS POR COBRAR NACIONALES M.N. | F33: CACERES AGUIRRE, ESTEFANNY TANIA | G33: B B01-00007528 | I33: PEN | J33: 55.6 | K33: 55.6 | M33: 55.6 | N33: A158698 | O33: PALIZA CAMAVILCA, JHOSSELYN JARUMY
A34: B B01-00007527 | B34: B B01-00007527 | C34: 46111 | D34: 46111 | E34: 1212001 FACTURAS POR COBRAR NACIONALES M.N. | F34: SANCHEZ HINOJOSA, MAYRA ALEJANDRA | G34: B B01-00007527 | I34: PEN | J34: 247.15 | K34: 247.15 | M34: 247.15 | N34: A158699 | O34: PALIZA CAMAVILCA, JHOSSELYN JARUMY
A35: B B01-00007526 | B35: B B01-00007526 | C35: 46111 | D35: 46111 | E35: 1212001 FACTURAS POR COBRAR NACIONALES M.N. | F35: BUSTAMANTE SOLANO, JAVIER ALVARO | G35: B B01-00007526 | I35: PEN | J35: 48.5 | K35: 48.5 | M35: 48.5 | N35: A158700 | O35: PALIZA CAMAVILCA, JHOSSELYN JARUMY
A36: B B01-00007524 | B36: B B01-00007524 | C36: 46111 | D36: 46111 | E36: 1212001 FACTURAS POR COBRAR NACIONALES M.N. | F36: CERPA SOLORZANO, CARLOS | G36: B B01-00007524 | I36: PEN | J36: 719.27 | K36: 719.27 | M36: 719.27 | N36: A158701 | O36: PALIZA CAMAVILCA, JHOSSELYN JARUMY
A37: B B01-00007522 | B37: B B01-00007522 | C37: 46111 | D37: 46111 | E37: 1212001 FACTURAS POR COBRAR NACIONALES M.N. | F37: SIFUENTES RODRIGUEZ, GUILLERMO DAVID | G37: B B01-00007522 | I37: PEN | J37: 209.43 | K37: 209.43 | M37: 209.43 | N37: A158702 | O37: PALIZA CAMAVILCA, JHOSSELYN JARUMY
A38: B B01-00007521 | B38: B B01-00007521 | C38: 46111 | D38: 46111 | E38: 1212001 FACTURAS POR COBRAR NACIONALES M.N. | F38: JERI LUCAS, LUIS EDUARDO | G38: B B01-00007521 | I38: PEN | J38: 169.11 | K38: 169.11 | M38: 169.11 | N38: A158703 | O38: PALIZA CAMAVILCA, JHOSSELYN JARUMY
A39: B B01-00007520 | B39: B B01-00007520 | C39: 46111 | D39: 46111 | E39: 1212001 FACTURAS POR COBRAR NACIONALES M.N. | F39: OLANO CORTEZ, LISSETTE NANCY | G39: B B01-00007520 | I39: PEN | J39: 107.2 | K39: 107.2 | M39: 107.2 | N39: A158704 | O39: PALIZA CAMAVILCA, JHOSSELYN JARUMY
A40: B B01-00007519 | B40: B B01-00007519 | C40: 46111 | D40: 46111 | E40: 1212001 FACTURAS POR COBRAR NACIONALES M.N. | F40: MENDOZA MARQUEZ, JONATHAN JEFF | G40: B B01-00007519 | I40: PEN | J40: 167.6 | K40: 167.6 | M40: 167.6 | N40: A158705 | O40: PALIZA CAMAVILCA, JHOSSELYN JARUMY
...

Sheet 1212xx2
A1: Asiento contable | B1: Número | C1: Fecha | D1: Fecha de vencimiento | E1: Cuenta | F1: Socio | G1: Etiqueta | H1: Referencia | I1: Moneda | J1: Importe en moneda | K1: Debe | L1: Haber | M1: Saldo | N1: Conciliación | O1: Creado por
A2: 1212002 FACTURAS POR COBRAR NACIONALES M.E. (94)
A3: CAMBI/2026/03/1722 (Ajuste diferencia cambio No realizada) | B3: CAMBI/2026/03/1722 | C3: 46112 | E3: 1212002 FACTURAS POR COBRAR NACIONALES M.E. | G3: Ajuste diferencia cambio No realizada | H3: Ajuste diferencia cambio No realizada | I3: USD | L3: 7705.43 | M3: -7705.43 | N3: A158607 | O3: BACKOFIS
A4: CAMBI/2026/03/1225 (Ajuste diferencia cambio No realizada) | B4: CAMBI/2026/03/1225 | C4: 46082 | E4: 1212002 FACTURAS POR COBRAR NACIONALES M.E. | G4: Ajuste diferencia cambio No realizada | H4: Ajuste diferencia cambio No realizada | I4: USD | K4: 11558.16 | M4: 11558.16 | N4: A152905 | O4: BACKOFIS
A5: CAMBI/2026/02/1233 (Ajuste diferencia cambio No realizada) | B5: CAMBI/2026/02/1233 | C5: 46081 | E5: 1212002 FACTURAS POR COBRAR NACIONALES M.E. | G5: Ajuste diferencia cambio No realizada | H5: Ajuste diferencia cambio No realizada | I5: USD | L5: 11558.16 | M5: -11558.16 | N5: A152905 | O5: BACKOFIS
A6: BCP02/2025/02242 | B6: BCP02/2025/02242 | C6: 46073 | E6: 1212002 FACTURAS POR COBRAR NACIONALES M.E. | F6: SCHRYVER LOGISTICS DEL PERU S.A.C | G6: F F01-00003105 | I6: USD | J6: -760.82 | L6: 2560.92 | M6: -2560.92 | N6: A127181 | O6: BARCENA BRAGA, KATTYA ADELAIDA
A7: CAMBI/2026/02/1066 (Ajuste diferencia cambio No realizada) | B7: CAMBI/2026/02/1066 | C7: 46054 | E7: 1212002 FACTURAS POR COBRAR NACIONALES M.E. | G7: Ajuste diferencia cambio No realizada | H7: Ajuste diferencia cambio No realizada | I7: USD | K7: 11570.34 | M7: 11570.34 | N7: A143767 | O7: BACKOFIS
A8: CAMBI/2026/01/3238 (Ajuste diferencia cambio No realizada) | B8: CAMBI/2026/01/3238 | C8: 46053 | E8: 1212002 FACTURAS POR COBRAR NACIONALES M.E. | G8: Ajuste diferencia cambio No realizada | H8: Ajuste diferencia cambio No realizada | I8: USD | L8: 11570.34 | M8: -11570.34 | N8: A143767 | O8: BACKOFIS
A9: CAMBI/2026/01/1026 (Ajuste diferencia cambio No realizada) | B9: CAMBI/2026/01/1026 | C9: 46023 | E9: 1212002 FACTURAS POR COBRAR NACIONALES M.E. | G9: Ajuste diferencia cambio No realizada | H9: Ajuste diferencia cambio No realizada | I9: USD | K9: 11337.62 | M9: 11337.62 | N9: A129931 | O9: ISMAEL AVILA
A10: CAMBI/2025/12/2426 (Ajuste diferencia cambio No realizada) | B10: CAMBI/2025/12/2426 | C10: 46022 | E10: 1212002 FACTURAS POR COBRAR NACIONALES M.E. | G10: Ajuste diferencia cambio No realizada | H10: Ajuste diferencia cambio No realizada | I10: USD | L10: 11337.62 | M10: -11337.62 | N10: A129931 | O10: ISMAEL AVILA
A11: PAPANT/2025/06381 (F F01-00003961) | B11: PAPANT/2025/06381 | C11: 46021 | D11: 46021 | E11: 1212002 FACTURAS POR COBRAR NACIONALES M.E. | F11: GARCIA FIESTAS JOSE AURELIO-10105455629 | G11: Pago de cliente $ 860.00 - GARCIA FIESTAS JOSE AURELIO-10105455629 - 30/12/2025 | H11: F F01-00003961 | I11: USD | J11: -860 | L11: 2899.92 | M11: -2899.92 | N11: A113746 | O11: ISMAEL AVILA
A12: F F01-00003961 | B12: F F01-00003961 | C12: 46021 | D12: 46021 | E12: 1212002 FACTURAS POR COBRAR NACIONALES M.E. | F12: GARCIA FIESTAS JOSE AURELIO-10105455629 | G12: F F01-00003961 | I12: USD | J12: 860 | K12: 2899.92 | M12: 2899.92 | N12: A113746 | O12: MATTO ASTETE, AUGUSTO WALTER
A13: CAMBI/2025/12/2425 (Ajuste diferencia cambio No realizada) | B13: CAMBI/2025/12/2425 | C13: 45992 | E13: 1212002 FACTURAS POR COBRAR NACIONALES M.E. | G13: Ajuste diferencia cambio No realizada | H13: Ajuste diferencia cambio No realizada | I13: USD | K13: 11366.71 | M13: 11366.71 | N13: A129874 | O13: ISMAEL AVILA
A14: PAPANT/2025/06375 (F F01-00003399) | B14: PAPANT/2025/06375 | C14: 45991 | D14: 45991 | E14: 1212002 FACTURAS POR COBRAR NACIONALES M.E. | F14: GARCIA FIESTAS JOSE AURELIO-10105455629 | G14: Pago de cliente $ 860.00 - GARCIA FIESTAS JOSE AURELIO-10105455629 - 30/11/2025 | H14: F F01-00003399 | I14: USD | J14: -860 | L14: 2896.48 | M14: -2896.48 | N14: A113733 | O14: ISMAEL AVILA
A15: F F01-00003399 | B15: F F01-00003399 | C15: 45991 | D15: 45991 | E15: 1212002 FACTURAS POR COBRAR NACIONALES M.E. | F15: GARCIA FIESTAS JOSE AURELIO-10105455629 | G15: F F01-00003399 | I15: USD | J15: 860 | K15: 2896.48 | M15: 2896.48 | N15: A113733 | O15: PALIZA CAMAVILCA, JHOSSELYN JARUMY
A16: CAMBI/2025/11/1649 (Ajuste diferencia cambio No realizada) | B16: CAMBI/2025/11/1649 | C16: 45991 | E16: 1212002 FACTURAS POR COBRAR NACIONALES M.E. | G16: Ajuste diferencia cambio No realizada | H16: Ajuste diferencia cambio No realizada | I16: USD | L16: 11366.71 | M16: -11366.71 | N16: A129874 | O16: ISMAEL AVILA
A17: F F01-00003105 | B17: F F01-00003105 | C17: 45973 | D17: 46003 | E17: 1212002 FACTURAS POR COBRAR NACIONALES M.E. | F17: SCHRYVER LOGISTICS DEL PERU S.A.C | G17: F F01-00003105 | I17: USD | J17: 760.82 | K17: 2560.92 | M17: 2560.92 | N17: A127181 | O17: PALIZA CAMAVILCA, JHOSSELYN JARUMY
A18: CAMBI/2025/11/1548 (Ajuste diferencia cambio No realizada) | B18: CAMBI/2025/11/1548 | C18: 45962 | E18: 1212002 FACTURAS POR COBRAR NACIONALES M.E. | G18: Ajuste diferencia cambio No realizada | H18: Ajuste diferencia cambio No realizada | I18: USD | K18: 10934.93 | M18: 10934.93 | N18: A128787 | O18: ISMAEL AVILA
A19: CAMBI/2025/10/2481 (Ajuste diferencia cambio No realizada) | B19: CAMBI/2025/10/2481 | C19: 45961 | E19: 1212002 FACTURAS POR COBRAR NACIONALES M.E. | G19: Ajuste diferencia cambio No realizada | H19: Ajuste diferencia cambio No realizada | I19: USD | L19: 10934.93 | M19: -10934.93 | N19: A128787 | O19: ISMAEL AVILA
A20: PAPANT/2025/04984 (F F01-00002970) | B20: PAPANT/2025/04984 | C20: 45960 | D20: 45960 | E20: 1212002 FACTURAS POR COBRAR NACIONALES M.E. | F20: GARCIA FIESTAS JOSE AURELIO-10105455629 | G20: Pago de cliente $ 860.00 - GARCIA FIESTAS JOSE AURELIO-10105455629 - 30/10/2025 | H20: F F01-00002970 | I20: USD | J20: -860 | L20: 2918.84 | M20: -2918.84 | N20: A113848 | O20: ISMAEL AVILA
A21: F F01-00002970 | B21: F F01-00002970 | C21: 45960 | D21: 45960 | E21: 1212002 FACTURAS POR COBRAR NACIONALES M.E. | F21: GARCIA FIESTAS JOSE AURELIO-10105455629 | G21: F F01-00002970 | I21: USD | J21: 860 | K21: 2918.84 | M21: 2918.84 | N21: A113848 | O21: PALIZA CAMAVILCA, JHOSSELYN JARUMY
A22: CAMBI/2025/10/1938 (Ajuste diferencia cambio No realizada) | B22: CAMBI/2025/10/1938 | C22: 45931 | E22: 1212002 FACTURAS POR COBRAR NACIONALES M.E. | G22: Ajuste diferencia cambio No realizada | H22: Ajuste diferencia cambio No realizada | I22: USD | K22: 8328.67 | M22: 8328.67 | N22: A121029 | O22: ISMAEL AVILA
A23: PAPANT/2025/04334 (F F01-00002539) | B23: PAPANT/2025/04334 | C23: 45930 | D23: 45930 | E23: 1212002 FACTURAS POR COBRAR NACIONALES M.E. | F23: GARCIA FIESTAS JOSE AURELIO-10105455629 | G23: Pago de cliente $ 860.00 - GARCIA FIESTAS JOSE AURELIO-10105455629 - 30/09/2025 | H23: F F01-00002539 | I23: USD | J23: -860 | L23: 3005.7 | M23: -3005.7 | N23: A113847 | O23: ISMAEL AVILA
A24: F F01-00002539 | B24: F F01-00002539 | C24: 45930 | D24: 45930 | E24: 1212002 FACTURAS POR COBRAR NACIONALES M.E. | F24: GARCIA FIESTAS JOSE AURELIO-10105455629 | G24: F F01-00002539 | I24: USD | J24: 860 | K24: 3005.7 | M24: 3005.7 | N24: A113847 | O24: PALIZA CAMAVILCA, JHOSSELYN JARUMY
A25: CAMBI/2025/09/2074 (Ajuste diferencia cambio No realizada) | B25: CAMBI/2025/09/2074 | C25: 45930 | E25: 1212002 FACTURAS POR COBRAR NACIONALES M.E. | G25: Ajuste diferencia cambio No realizada | H25: Ajuste diferencia cambio No realizada | I25: USD | L25: 8328.67 | M25: -8328.67 | N25: A121029 | O25: ISMAEL AVILA
A26: CAMBI/2025/09/1961 (EXTORNO DIFERENCIA DE CAMBIO AGOSTO) | B26: CAMBI/2025/09/1961 | C26: 45901 | E26: 1212002 FACTURAS POR COBRAR NACIONALES M.E. | G26: EXTORNO DIFERENCIA DE CAMBIO AGOSTO | H26: EXTORNO DIFERENCIA DE CAMBIO AGOSTO | I26: USD | K26: 33.48 | M26: 33.48 | N26: A119725 | O26: ISMAEL AVILA
A27: CAMBI/2025/09/1797 (Ajuste diferencia cambio No realizada) | B27: CAMBI/2025/09/1797 | C27: 45901 | E27: 1212002 FACTURAS POR COBRAR NACIONALES M.E. | G27: Ajuste diferencia cambio No realizada | H27: Ajuste diferencia cambio No realizada | I27: USD | K27: 6425.48 | M27: 6425.48 | N27: A118927 | O27: ISMAEL AVILA
A28: CAMBI/2025/08/2388 (AJUSTE DE DIFERENCIA DE CAMBIO AGOSTO) | B28: CAMBI/2025/08/2388 | C28: 45900 | E28: 1212002 FACTURAS POR COBRAR NACIONALES M.E. | G28: AJUSTE DE DIFERENCIA DE CAMBIO AGOSTO | H28: AJUSTE DE DIFERENCIA DE CAMBIO AGOSTO | I28: USD | L28: 33.48 | M28: -33.48 | N28: A119725 | O28: ISMAEL AVILA
A29: CAMBI/2025/08/2378 (Ajuste diferencia cambio No realizada) | B29: CAMBI/2025/08/2378 | C29: 45900 | E29: 1212002 FACTURAS POR COBRAR NACIONALES M.E. | G29: Ajuste diferencia cambio No realizada | H29: Ajuste diferencia cambio No realizada | I29: USD | L29: 6425.48 | M29: -6425.48 | N29: A118927 | O29: ISMAEL AVILA
A30: PAPANT/2025/03696 (F F01-00002123) | B30: PAPANT/2025/03696 | C30: 45895 | D30: 45895 | E30: 1212002 FACTURAS POR COBRAR NACIONALES M.E. | F30: GARCIA FIESTAS JOSE AURELIO-10105455629 | G30: Pago de cliente $ 860.00 - GARCIA FIESTAS JOSE AURELIO-10105455629 - 26/08/2025 | H30: F F01-00002123 | I30: USD | J30: -860 | L30: 3036.66 | M30: -3036.66 | N30: A113846 | O30: ISMAEL AVILA
A31: F F01-00002123 | B31: F F01-00002123 | C31: 45895 | D31: 45895 | E31: 1212002 FACTURAS POR COBRAR NACIONALES M.E. | F31: GARCIA FIESTAS JOSE AURELIO-10105455629 | G31: F F01-00002123 | I31: USD | J31: 860 | K31: 3036.66 | M31: 3036.66 | N31: A113846 | O31: PALIZA CAMAVILCA, JHOSSELYN JARUMY
A32: CAMBI/2025/08/1883 (Ajuste diferencia cambio No realizada) | B32: CAMBI/2025/08/1883 | C32: 45870 | E32: 1212002 FACTURAS POR COBRAR NACIONALES M.E. | G32: Ajuste diferencia cambio No realizada | H32: Ajuste diferencia cambio No realizada | I32: USD | K32: 5003 | M32: 5003 | N32: A114311 | O32: ISMAEL AVILA
A33: CAMBI/2025/07/1286 (Ajuste diferencia cambio No realizada) | B33: CAMBI/2025/07/1286 | C33: 45869 | E33: 1212002 FACTURAS POR COBRAR NACIONALES M.E. | G33: Ajuste diferencia cambio No realizada | H33: Ajuste diferencia cambio No realizada | I33: USD | L33: 5003 | M33: -5003 | N33: A114311 | O33: ISMAEL AVILA
A34: PAPANT/2025/03688 (F F01-00001775) | B34: PAPANT/2025/03688 | C34: 45862 | D34: 45862 | E34: 1212002 FACTURAS POR COBRAR NACIONALES M.E. | F34: GARCIA FIESTAS JOSE AURELIO-10105455629 | G34: Pago de cliente $ 860.00 - GARCIA FIESTAS JOSE AURELIO-10105455629 - 24/07/2025 | H34: F F01-00001775 | I34: USD | J34: -860 | L34: 3062.46 | M34: -3062.46 | N34: A113841 | O34: ISMAEL AVILA
A35: F F01-00001775 | B35: F F01-00001775 | C35: 45862 | D35: 45862 | E35: 1212002 FACTURAS POR COBRAR NACIONALES M.E. | F35: GARCIA FIESTAS JOSE AURELIO-10105455629 | G35: F F01-00001775 | I35: USD | J35: 860 | K35: 3062.46 | M35: 3062.46 | N35: A113841 | O35: PALIZA CAMAVILCA, JHOSSELYN JARUMY
A36: CAMBI/2025/07/1421 (EXTORNO DIFERENCIA DE CAMBIO JUNIO) | B36: CAMBI/2025/07/1421 | C36: 45839 | E36: 1212002 FACTURAS POR COBRAR NACIONALES M.E. | G36: EXTORNO DIFERENCIA DE CAMBIO JUNIO | H36: EXTORNO DIFERENCIA DE CAMBIO JUNIO | I36: USD | K36: 299.64 | M36: 299.64 | N36: A122050 | O36: ISMAEL AVILA
A37: CAMBI/2025/07/1193 (Ajuste diferencia cambio No realizada) | B37: CAMBI/2025/07/1193 | C37: 45839 | E37: 1212002 FACTURAS POR COBRAR NACIONALES M.E. | G37: Ajuste diferencia cambio No realizada | H37: Ajuste diferencia cambio No realizada | I37: USD | K37: 6046.01 | M37: 6046.01 | N37: A114443 | O37: ISMAEL AVILA
A38: CAMBI/2025/06/2287 (AJUSTE DE DIFERENCIA DE CAMBIO JUNIO) | B38: CAMBI/2025/06/2287 | C38: 45838 | E38: 1212002 FACTURAS POR COBRAR NACIONALES M.E. | G38: AJUSTE DE DIFERENCIA DE CAMBIO JUNIO | H38: AJUSTE DE DIFERENCIA DE CAMBIO JUNIO | I38: USD | L38: 299.64 | M38: -299.64 | N38: A122050 | O38: ISMAEL AVILA
A39: CAMBI/2025/06/2154 (Ajuste diferencia cambio No realizada) | B39: CAMBI/2025/06/2154 | C39: 45838 | E39: 1212002 FACTURAS POR COBRAR NACIONALES M.E. | G39: Ajuste diferencia cambio No realizada | H39: Ajuste diferencia cambio No realizada | I39: USD | L39: 6046.01 | M39: -6046.01 | N39: A114443 | O39: ISMAEL AVILA
A40: PAPANT/2025/03679 (F F01-00001545) | B40: PAPANT/2025/03679 | C40: 45835 | D40: 45835 | E40: 1212002 FACTURAS POR COBRAR NACIONALES M.E. | F40: GARCIA FIESTAS JOSE AURELIO-10105455629 | G40: Pago de cliente $ 860.00 - GARCIA FIESTAS JOSE AURELIO-10105455629 - 27/06/2025 | H40: F F01-00001545 | I40: USD | J40: -860 | L40: 3071.92 | M40: -3071.92 | N40: A113804 | O40: ISMAEL AVILA
...

Sheet 1212xx3
A1: Asiento contable | B1: Número | C1: Fecha | D1: Fecha de vencimiento | E1: Cuenta | F1: Socio | G1: Etiqueta | H1: Referencia | I1: Moneda | J1: Importe en moneda | K1: Debe | L1: Haber | M1: Saldo | N1: Conciliación | O1: Creado por
A2: 1212003 FACTURAS POR COBRAR DEL EXTERIOR (2208)
A3: F F15-00000353 | B3: F F15-00000353 | C3: 46112 | D3: 46112 | E3: 1212003 FACTURAS POR COBRAR DEL EXTERIOR | F3: MONTECO S.A | G3: F F15-00000353 | I3: USD | J3: 207.38 | K3: 724.79 | M3: 724.79 | N3: A144647 | O3: PALIZA CAMAVILCA, JHOSSELYN JARUMY
A4: CAMBI/2026/03/1722 (Ajuste diferencia cambio No realizada) | B4: CAMBI/2026/03/1722 | C4: 46112 | E4: 1212003 FACTURAS POR COBRAR DEL EXTERIOR | G4: Ajuste diferencia cambio No realizada | H4: Ajuste diferencia cambio No realizada | I4: USD | K4: 296591.53 | M4: 296591.53 | N4: A158608 | O4: BACKOFIS
A5: F BILL/2026/03/1846 (APLICACION DE FT MKT COMO SALDO A FAVOR DE [...]) | B5: F BILL/2026/03/1846 | C5: 46107 | E5: 1212003 FACTURAS POR COBRAR DEL EXTERIOR | F5: MONTECO ANIMAL HEALTH S.A. DE C.V. | G5: F F15-00000287 | H5: APLICACION DE FT MKT COMO SALDO A FAVOR DE FT POR COBRAR DE MONTECO SV | I5: USD | J5: -38425.9 | L5: 133261.02 | M5: -133261.02 | O5: MONTERO VILCAS, JOSE GORGE
A6: CAMBI/2026/03/0903 | B6: CAMBI/2026/03/0903 | C6: 46107 | E6: 1212003 FACTURAS POR COBRAR DEL EXTERIOR | F6: MONTECO ANIMAL HEALTH S.A. DE C.V. | G6: Diferencia en tipo de cambio de moneda | I6: USD | K6: 3688.88 | M6: 3688.88 | O6: MONTERO VILCAS, JOSE GORGE
A7: F F15-00000347 | B7: F F15-00000347 | C7: 46098 | D7: 46143 | E7: 1212003 FACTURAS POR COBRAR DEL EXTERIOR | F7: GLOBALVET | G7: F F15-00000347 | I7: USD | J7: 9200 | K7: 31638.8 | M7: 31638.8 | O7: PARKER MENDOZA, VANESSA ALEXANDRA
A8: F D15-00000043 | B8: F D15-00000043 | C8: 46098 | D8: 46098 | E8: 1212003 FACTURAS POR COBRAR DEL EXTERIOR | F8: GLOBALVET | G8: F D15-00000043 | I8: USD | J8: 750 | K8: 2579.25 | M8: 2579.25 | O8: PALIZA CAMAVILCA, JHOSSELYN JARUMY
A9: F F15-00000345 | B9: F F15-00000345 | C9: 46094 | D9: 46184 | E9: 1212003 FACTURAS POR COBRAR DEL EXTERIOR | F9: GRUPO GRANDES ROMAN S.A. | G9: F F15-00000345 | I9: USD | J9: 157038.36 | K9: 541625.34 | M9: 541625.34 | O9: PARKER MENDOZA, VANESSA ALEXANDRA
A10: E B01-00000324 | B10: E B01-00000324 | C10: 46091 | D10: 46091 | E10: 1212003 FACTURAS POR COBRAR DEL EXTERIOR | F10: DYNTEC SPOL. S.R.O | G10: E B01-00000345 | I10: USD | J10: 9799.71 | K10: 34230.39 | M10: 34230.39 | N10: A158917 | O10: PALIZA CAMAVILCA, JHOSSELYN JARUMY
A11: F F15-00000340 | B11: F F15-00000340 | C11: 46087 | D11: 46132 | E11: 1212003 FACTURAS POR COBRAR DEL EXTERIOR | F11: MONTECO ANIMAL HEALTH S.A. DE C.V. | G11: F F15-00000340 | I11: USD | J11: 6873.6 | K11: 23590.2 | M11: 23590.2 | N11: A150402 | O11: PARKER MENDOZA, VANESSA ALEXANDRA
A12: F D15-00000042 | B12: F D15-00000042 | C12: 46087 | D12: 46087 | E12: 1212003 FACTURAS POR COBRAR DEL EXTERIOR | F12: MONTECO ANIMAL HEALTH S.A. DE C.V. | G12: F D15-00000042 | I12: USD | J12: 750 | K12: 2574 | M12: 2574 | N12: A150403 | O12: PALIZA CAMAVILCA, JHOSSELYN JARUMY
A13: E 001-00000430 | B13: E 001-00000430 | C13: 46073 | D13: 46073 | E13: 1212003 FACTURAS POR COBRAR DEL EXTERIOR | F13: MILIFAR SHPK | G13: E 001-00000430 | I13: USD | J13: 2 | K13: 6.73 | M13: 6.73 | O13: PARKER MENDOZA, VANESSA ALEXANDRA
A14: E 001-00000425 | B14: E 001-00000425 | C14: 46070 | D14: 46070 | E14: 1212003 FACTURAS POR COBRAR DEL EXTERIOR | F14: MY PETS VETERINARY CENTER W.L.L | G14: E 001-00000425 | I14: USD | J14: 4 | K14: 13.43 | M14: 13.43 | O14: PARKER MENDOZA, VANESSA ALEXANDRA
A15: CAMBI/2026/02/0132 | B15: CAMBI/2026/02/0132 | C15: 46056 | E15: 1212003 FACTURAS POR COBRAR DEL EXTERIOR | F15: UNIVET S.R.L. | G15: Diferencia en tipo de cambio de moneda | I15: USD | L15: 11.03 | M15: -11.03 | O15: MONTERO VILCAS, JOSE GORGE
A16: BCP02/2025/02147 | B16: BCP02/2025/02147 | C16: 46056 | E16: 1212003 FACTURAS POR COBRAR DEL EXTERIOR | F16: UNIVET S.R.L. | G16: F F15-00000285 | I16: USD | J16: -3675.71 | L16: 12383.47 | M16: -12383.47 | O16: MONTERO VILCAS, JOSE GORGE
A17: F F15-00000323 | B17: F F15-00000323 | C17: 46051 | D17: 46156 | E17: 1212003 FACTURAS POR COBRAR DEL EXTERIOR | F17: GRUPO COMERCIAL MONTECO S.A. | G17: F F15-00000323 | I17: USD | J17: 45315.6 | K17: 151580.68 | M17: 151580.68 | N17: A158872 | O17: PARKER MENDOZA, VANESSA ALEXANDRA
A18: F F15-00000323 | B18: F F15-00000323 | C18: 46051 | D18: 46171 | E18: 1212003 FACTURAS POR COBRAR DEL EXTERIOR | F18: GRUPO COMERCIAL MONTECO S.A. | G18: F F15-00000323 | I18: USD | J18: 45315.6 | K18: 151580.68 | M18: 151580.68 | O18: PARKER MENDOZA, VANESSA ALEXANDRA
A19: F F15-00000320 | B19: F F15-00000320 | C19: 46042 | D19: 46042 | E19: 1212003 FACTURAS POR COBRAR DEL EXTERIOR | F19: MONTECO S.A | G19: F F15-00000320 | I19: USD | J19: 19656 | K19: 66162.1 | M19: 66162.1 | O19: PARKER MENDOZA, VANESSA ALEXANDRA
A20: F F15-00000316 | B20: F F15-00000316 | C20: 46042 | D20: 46087 | E20: 1212003 FACTURAS POR COBRAR DEL EXTERIOR | F20: GRUPO GRANDES ROMAN S.A. | G20: F F15-00000316 | I20: USD | J20: 33566.8 | K20: 112985.87 | M20: 112985.87 | N20: A143463 | O20: PARKER MENDOZA, VANESSA ALEXANDRA
A21: F C15-00000040 | B21: F C15-00000040 | C21: 46024 | D21: 46024 | E21: 1212003 FACTURAS POR COBRAR DEL EXTERIOR | F21: GRUPO GRANDES ROMAN S.A. | I21: USD | J21: -296.4 | L21: 998.28 | M21: -998.28 | O21: PALIZA CAMAVILCA, JHOSSELYN JARUMY
A22: CAMBI/2026/01/0975 | B22: CAMBI/2026/01/0975 | C22: 46024 | E22: 1212003 FACTURAS POR COBRAR DEL EXTERIOR | F22: GRUPO GRANDES ROMAN S.A. | G22: Diferencia en tipo de cambio de moneda | I22: USD | L22: 1.18 | M22: -1.18 | O22: MONTERO VILCAS, JOSE GORGE
A23: F F15-00000307 | B23: F F15-00000307 | C23: 46022 | D23: 46142 | E23: 1212003 FACTURAS POR COBRAR DEL EXTERIOR | F23: UNIVET S.R.L. | G23: F F15-00000307 | I23: USD | J23: 355.2 | K23: 1196.67 | M23: 1196.67 | O23: PARKER MENDOZA, VANESSA ALEXANDRA
A24: F F15-00000307 | B24: F F15-00000307 | C24: 46022 | D24: 46127 | E24: 1212003 FACTURAS POR COBRAR DEL EXTERIOR | F24: UNIVET S.R.L. | G24: F F15-00000307 | I24: USD | J24: 355.2 | K24: 1196.67 | M24: 1196.67 | O24: PARKER MENDOZA, VANESSA ALEXANDRA
A25: F F15-00000299 | B25: F F15-00000299 | C25: 46021 | D25: 46141 | E25: 1212003 FACTURAS POR COBRAR DEL EXTERIOR | F25: GRUPO GRANDES ROMAN S.A. | G25: F F15-00000299 | I25: USD | J25: 158803.96 | K25: 535486.97 | M25: 535486.97 | O25: PARKER MENDOZA, VANESSA ALEXANDRA
A26: F F15-00000299 | B26: F F15-00000299 | C26: 46021 | D26: 46126 | E26: 1212003 FACTURAS POR COBRAR DEL EXTERIOR | F26: GRUPO GRANDES ROMAN S.A. | G26: F F15-00000299 | I26: USD | J26: 158803.97 | K26: 535486.97 | M26: 535486.97 | O26: PARKER MENDOZA, VANESSA ALEXANDRA
A27: F F15-00000297 | B27: F F15-00000297 | C27: 46021 | D27: 46096 | E27: 1212003 FACTURAS POR COBRAR DEL EXTERIOR | F27: GLOBALVET | G27: F F15-00000297 | I27: USD | J27: 88652 | K27: 298934.54 | M27: 298934.54 | N27: A159297 | O27: PARKER MENDOZA, VANESSA ALEXANDRA
A28: F F15-00000289 | B28: F F15-00000289 | C28: 46021 | D28: 46141 | E28: 1212003 FACTURAS POR COBRAR DEL EXTERIOR | F28: GRUPO COMERCIAL MONTECO S.A. | G28: F F15-00000289 | I28: USD | J28: 158333.02 | K28: 533898.93 | M28: 533898.93 | O28: PARKER MENDOZA, VANESSA ALEXANDRA
A29: F F15-00000289 | B29: F F15-00000289 | C29: 46021 | D29: 46126 | E29: 1212003 FACTURAS POR COBRAR DEL EXTERIOR | F29: GRUPO COMERCIAL MONTECO S.A. | G29: F F15-00000289 | I29: USD | J29: 158333.02 | K29: 533898.94 | M29: 533898.94 | N29: A158871 | O29: PARKER MENDOZA, VANESSA ALEXANDRA
A30: F F15-00000287 | B30: F F15-00000287 | C30: 46021 | D30: 46141 | E30: 1212003 FACTURAS POR COBRAR DEL EXTERIOR | F30: MONTECO ANIMAL HEALTH S.A. DE C.V. | G30: F F15-00000287 | I30: USD | J30: 183418.15 | K30: 618486.02 | M30: 618486.02 | O30: PARKER MENDOZA, VANESSA ALEXANDRA
A31: F F15-00000287 | B31: F F15-00000287 | C31: 46021 | D31: 46126 | E31: 1212003 FACTURAS POR COBRAR DEL EXTERIOR | F31: MONTECO ANIMAL HEALTH S.A. DE C.V. | G31: F F15-00000287 | I31: USD | J31: 183418.15 | K31: 618486.02 | M31: 618486.02 | O31: PARKER MENDOZA, VANESSA ALEXANDRA
A32: F F15-00000285 | B32: F F15-00000285 | C32: 46021 | D32: 46126 | E32: 1212003 FACTURAS POR COBRAR DEL EXTERIOR | F32: UNIVET S.R.L. | G32: F F15-00000285 | I32: USD | J32: 270165.02 | K32: 910996.43 | M32: 910996.43 | O32: PARKER MENDOZA, VANESSA ALEXANDRA
A33: F F15-00000283 | B33: F F15-00000283 | C33: 46021 | D33: 46066 | E33: 1212003 FACTURAS POR COBRAR DEL EXTERIOR | F33: CYCLOVET - SARL. | G33: F F15-00000283 | I33: USD | J33: 72429.6 | K33: 244232.61 | M33: 244232.61 | N33: A148869 | O33: PARKER MENDOZA, VANESSA ALEXANDRA
A34: F F15-00000282 | B34: F F15-00000282 | C34: 46021 | D34: 46066 | E34: 1212003 FACTURAS POR COBRAR DEL EXTERIOR | F34: CYCLOVET - SARL. | G34: F F15-00000282 | I34: USD | J34: 63580.68 | K34: 214394.05 | M34: 214394.05 | N34: A148868 | O34: PARKER MENDOZA, VANESSA ALEXANDRA
A35: F F15-00000281 | B35: F F15-00000281 | C35: 46021 | D35: 46066 | E35: 1212003 FACTURAS POR COBRAR DEL EXTERIOR | F35: CYCLOVET - SARL. | G35: F F15-00000281 | I35: USD | J35: 40000 | K35: 134880 | M35: 134880 | N35: A148867 | O35: PARKER MENDOZA, VANESSA ALEXANDRA
A36: F F15-00000279 | B36: F F15-00000279 | C36: 46021 | D36: 46021 | E36: 1212003 FACTURAS POR COBRAR DEL EXTERIOR | F36: MONTECO S.A | G36: F F15-00000279 | I36: USD | J36: 537900.9 | K36: 1813801.8 | M36: 1813801.8 | O36: PARKER MENDOZA, VANESSA ALEXANDRA
A37: F D15-00000036 | B37: F D15-00000036 | C37: 46021 | D37: 46021 | E37: 1212003 FACTURAS POR COBRAR DEL EXTERIOR | F37: SOCIEDAD NACIONAL PECUARIA S.A. | G37: F D15-00000036 | I37: USD | J37: 500 | K37: 1686 | M37: 1686 | N37: A142982 | O37: PALIZA CAMAVILCA, JHOSSELYN JARUMY
A38: PAPANT/2025/05849 (F D15-00000035) | B38: PAPANT/2025/05849 | C38: 46014 | D38: 46014 | E38: 1212003 FACTURAS POR COBRAR DEL EXTERIOR | F38: BREMER LANKA (PVT) LTD. | G38: Pago de cliente $ 600.00 - BREMER LANKA (PVT) LTD. - 23/12/2025 | H38: F D15-00000035 | I38: USD | J38: -600 | L38: 2023.2 | M38: -2023.2 | N38: A142959 | O38: MONTERO VILCAS, JOSE GORGE
A39: F D15-00000035 | B39: F D15-00000035 | C39: 46014 | D39: 46014 | E39: 1212003 FACTURAS POR COBRAR DEL EXTERIOR | F39: BREMER LANKA (PVT) LTD. | G39: F D15-00000035 | I39: USD | J39: 750 | K39: 2529 | M39: 2529 | N39: A142959 | O39: PALIZA CAMAVILCA, JHOSSELYN JARUMY
A40: CAMBI/2026/03/0085 | B40: CAMBI/2026/03/0085 | C40: 46083 | E40: 1212003 FACTURAS POR COBRAR DEL EXTERIOR | F40: SOCIEDAD NACIONAL PECUARIA S.A. | G40: Diferencia en tipo de cambio de moneda | I40: USD | L40: 99.76 | M40: -99.76 | N40: A142981 | O40: MONTERO VILCAS, JOSE GORGE
...

Sheet 122xx1
A1: Asiento contable | B1: Número | C1: Fecha | D1: Fecha de vencimiento | E1: Cuenta | F1: Socio | G1: Etiqueta | H1: Referencia | I1: Moneda | J1: Importe en moneda | K1: Debe | L1: Haber | M1: Saldo | N1: Conciliación | O1: Creado por
A2: 1220001 ANTICIPOS CLIENTES NACIONAL M.N. (412)
A3: BCP01/2025/15559 | B3: BCP01/2025/15559 | C3: 46112 | E3: 1220001 ANTICIPOS CLIENTES NACIONAL M.N. | F3: CAMPOS ALONZO ANDRES EDUARDO | G3: ABONO | I3: PEN | J3: -92.9 | L3: 92.9 | M3: -92.9 | N3: A149375 | O3: BARCENA BRAGA, KATTYA ADELAIDA
A4: BCP01/2025/15501 | B4: BCP01/2025/15501 | C4: 46111 | E4: 1220001 ANTICIPOS CLIENTES NACIONAL M.N. | F4: CONSTRUCTORA Y MULTISERVICIOS AGROVET J&S SOCIEDAD ANONIMA CERRADA | G4: SALDO | I4: PEN | J4: -10 | L4: 10 | M4: -10 | O4: BARCENA BRAGA, KATTYA ADELAIDA
A5: BCP01/2025/15499 | B5: BCP01/2025/15499 | C5: 46111 | E5: 1220001 ANTICIPOS CLIENTES NACIONAL M.N. | F5: AGRIMEC VETERINARIA E.I.R.L. - AGRIMEC VET E.I.R.L. | G5: DE AGRIMEC VET EIRL | I5: PEN | J5: -15276.28 | L5: 15276.28 | M5: -15276.28 | O5: BARCENA BRAGA, KATTYA ADELAIDA
A6: BBVA1/2025/05541 | B6: BBVA1/2025/05541 | C6: 46111 | E6: 1220001 ANTICIPOS CLIENTES NACIONAL M.N. | F6: AGROVETERINARIA Y MULTISERVICIOS "DAGA" SOCIEDAD COMERCIAL DE RESPONSABILIDAD LIMITADA | G6: ABONO | I6: PEN | J6: -7241.93 | L6: 7241.93 | M6: -7241.93 | O6: BARCENA BRAGA, KATTYA ADELAIDA
A7: BCP01/2025/15370 | B7: BCP01/2025/15370 | C7: 46106 | E7: 1220001 ANTICIPOS CLIENTES NACIONAL M.N. | F7: GONZALES MEDINA JOHANNA PATRICIA | G7: SALDO | I7: PEN | J7: -43.89 | L7: 43.89 | M7: -43.89 | O7: BARCENA BRAGA, KATTYA ADELAIDA
A8: BCP01/2025/15268 | B8: BCP01/2025/15268 | C8: 46101 | E8: 1220001 ANTICIPOS CLIENTES NACIONAL M.N. | F8: VARIOS | G8: ABONO NO IDENTIFICADOS | I8: PEN | J8: -5017.87 | L8: 5017.87 | M8: -5017.87 | O8: BARCENA BRAGA, KATTYA ADELAIDA
A9: BCP01/2025/15265 | B9: BCP01/2025/15265 | C9: 46101 | E9: 1220001 ANTICIPOS CLIENTES NACIONAL M.N. | F9: PHARMAVET MARKET E.I.R.L. | G9: ABONO | I9: PEN | J9: -15284.04 | L9: 15284.04 | M9: -15284.04 | N9: A144252 | O9: BARCENA BRAGA, KATTYA ADELAIDA
A10: BBVA1/2025/05284 | B10: BBVA1/2025/05284 | C10: 46099 | E10: 1220001 ANTICIPOS CLIENTES NACIONAL M.N. | F10: VARIOS | G10: ABONO NO IDENTIFICADO | I10: PEN | J10: -133 | L10: 133 | M10: -133 | O10: BARCENA BRAGA, KATTYA ADELAIDA
A11: IBK02/2025/03473 | B11: IBK02/2025/03473 | C11: 46098 | E11: 1220001 ANTICIPOS CLIENTES NACIONAL M.N. | F11: VARIOS | G11: ABONO NO IDENTIFICADO | I11: PEN | J11: -400 | L11: 400 | M11: -400 | O11: BARCENA BRAGA, KATTYA ADELAIDA
A12: BCP01/2025/15154 | B12: BCP01/2025/15154 | C12: 46098 | E12: 1220001 ANTICIPOS CLIENTES NACIONAL M.N. | F12: VARIOS | G12: ABONO NO IDENTIFICADO | I12: PEN | J12: -1335 | L12: 1335 | M12: -1335 | O12: BARCENA BRAGA, KATTYA ADELAIDA
A13: BCP01/2025/14815 | B13: BCP01/2025/14815 | C13: 46097 | E13: 1220001 ANTICIPOS CLIENTES NACIONAL M.N. | F13: CONSTRUCTORA Y MULTISERVICIOS AGROVET J&S SOCIEDAD ANONIMA CERRADA | G13: SALDO A FVAOR PE | I13: PEN | J13: 348.59 | K13: 348.59 | M13: 348.59 | O13: BARCENA BRAGA, KATTYA ADELAIDA
A14: BCP01/2025/14260 | B14: BCP01/2025/14260 | C14: 46076 | E14: 1220001 ANTICIPOS CLIENTES NACIONAL M.N. | F14: VARIOS | G14: SALDO | I14: PEN | J14: -73 | L14: 73 | M14: -73 | O14: BARCENA BRAGA, KATTYA ADELAIDA
A15: BCP01/2025/14105 | B15: BCP01/2025/14105 | C15: 46071 | E15: 1220001 ANTICIPOS CLIENTES NACIONAL M.N. | F15: PHARMAVET MARKET E.I.R.L. | G15: Saldo pendiente: S/ 12,909.50 | I15: PEN | J15: -199.97 | L15: 199.97 | M15: -199.97 | O15: BARCENA BRAGA, KATTYA ADELAIDA
A16: BCP01/2025/13699 | B16: BCP01/2025/13699 | C16: 46064 | E16: 1220001 ANTICIPOS CLIENTES NACIONAL M.N. | F16: EMPRESA COMERCIALIZADORA DE INSUMOS Y PRODUCTOS AGROPECUARIOS Y TRANSPORTES S.R.L. | G16: SALDO A FAVOR | I16: PEN | J16: 170.57 | K16: 170.57 | M16: 170.57 | O16: BARCENA BRAGA, KATTYA ADELAIDA
A17: BCP01/2025/13693 | B17: BCP01/2025/13693 | C17: 46064 | E17: 1220001 ANTICIPOS CLIENTES NACIONAL M.N. | F17: FUMIGACIONES DEL SUR E.I.R.L. | G17: SALDO PE | I17: PEN | J17: -600 | L17: 600 | M17: -600 | O17: BARCENA BRAGA, KATTYA ADELAIDA
A18: BCP01/2025/13593 | B18: BCP01/2025/13593 | C18: 46059 | E18: 1220001 ANTICIPOS CLIENTES NACIONAL M.N. | F18: SUPERMERCADOS PARA MASCOTAS DEL PERU S.A.C. | G18: SALDO A FAVOR | I18: PEN | J18: -35.4 | L18: 35.4 | M18: -35.4 | O18: PEREIRA FUENTES, EIGLY YARITZA
A19: BCP01/2025/13510 | B19: BCP01/2025/13510 | C19: 46057 | E19: 1220001 ANTICIPOS CLIENTES NACIONAL M.N. | F19: PETS SHOP LA MOLINA SOCIEDAD ANONIMA CERRADA | G19: SALDO A FAVOR | I19: PEN | J19: -683.32 | L19: 683.32 | M19: -683.32 | O19: PEREIRA FUENTES, EIGLY YARITZA
A20: BBVA1/2025/04579 | B20: BBVA1/2025/04579 | C20: 46051 | E20: 1220001 ANTICIPOS CLIENTES NACIONAL M.N. | F20: AGROVETERINARIA Y MULTISERVICIOS "DAGA" SOCIEDAD COMERCIAL DE RESPONSABILIDAD LIMITADA | G20: SALDO A FAVOR | I20: PEN | J20: -3406.33 | L20: 3406.33 | M20: -3406.33 | O20: PEREIRA FUENTES, EIGLY YARITZA
A21: BCP01/2025/13309 | B21: BCP01/2025/13309 | C21: 46049 | E21: 1220001 ANTICIPOS CLIENTES NACIONAL M.N. | F21: PHARMAVET MARKET E.I.R.L. | G21: saldo a favor | I21: PEN | J21: -640.5 | L21: 640.5 | M21: -640.5 | O21: MONTERO VILCAS, JOSE GORGE
A22: BCP01/2025/13304 | B22: BCP01/2025/13304 | C22: 46049 | E22: 1220001 ANTICIPOS CLIENTES NACIONAL M.N. | F22: PHARMAVET MARKET E.I.R.L. | G22: saldo a favor por FT F F01-00004319 | I22: PEN | J22: -1708 | L22: 1708 | M22: -1708 | O22: MONTERO VILCAS, JOSE GORGE
A23: PAPANT/2025/06651 (F F01-00004168) | B23: PAPANT/2025/06651 | C23: 46042 | D23: 46042 | E23: 1220001 ANTICIPOS CLIENTES NACIONAL M.N. | F23: AGUIVET S.A.C. | G23: Pago de cliente S/ 6,553.18 - AGUIVET S.A.C. - 20/01/2026 | H23: F F01-00004168 | I23: PEN | J23: 6553.18 | K23: 6553.18 | M23: 6553.18 | O23: MONTERO VILCAS, JOSE GORGE
A24: BCP01/2025/12997 | B24: BCP01/2025/12997 | C24: 46037 | E24: 1220001 ANTICIPOS CLIENTES NACIONAL M.N. | F24: AGRIVET E INVERSIONES S.A.C. | G24: DE AGRIVET E INVERSION SALDO | I24: PEN | J24: -371.29 | L24: 371.29 | M24: -371.29 | O24: BARCENA BRAGA, KATTYA ADELAIDA
A25: PAPANT/2025/06663 (F F01-00004004) | B25: PAPANT/2025/06663 | C25: 46029 | D25: 46029 | E25: 1220001 ANTICIPOS CLIENTES NACIONAL M.N. | F25: VETERINARIA SAN PABLO E.I.R.L. | G25: Pago de cliente S/ 208.65 - VETERINARIA SAN PABLO E.I.R.L. - 07/01/2026 | H25: F F01-00004004 | I25: PEN | J25: 208.65 | K25: 208.65 | M25: 208.65 | O25: MONTERO VILCAS, JOSE GORGE
A26: BCP01/2025/12118 | B26: BCP01/2025/12118 | C26: 46028 | E26: 1220001 ANTICIPOS CLIENTES NACIONAL M.N. | F26: GALIANO FRANCO, LESLI GIANINA | G26: SALDO A FAVOR | I26: PEN | J26: -4.02 | L26: 4.02 | M26: -4.02 | O26: PEREIRA FUENTES, EIGLY YARITZA
A27: PAPANT/2025/08273 (B B01-00004471) | B27: PAPANT/2025/08273 | C27: 46023 | D27: 46023 | E27: 1220001 ANTICIPOS CLIENTES NACIONAL M.N. | F27: SANCHEZ YEPEZ CARLA STEFANY | G27: Pago de cliente S/ 75.00 - SANCHEZ YEPEZ CARLA STEFANY - 01/01/2026 | H27: B B01-00004471 | I27: PEN | J27: 75 | K27: 75 | M27: 75 | O27: BARCENA BRAGA, KATTYA ADELAIDA
A28: BCP01/2025/11893 | B28: BCP01/2025/11893 | C28: 46017 | E28: 1220001 ANTICIPOS CLIENTES NACIONAL M.N. | F28: AGRIVET E INVERSIONES S.A.C. | G28: SALDO A FAVOR | I28: PEN | J28: -200.86 | L28: 200.86 | M28: -200.86 | O28: PEREIRA FUENTES, EIGLY YARITZA
A29: BCP01/2025/11888 | B29: BCP01/2025/11888 | C29: 46017 | E29: 1220001 ANTICIPOS CLIENTES NACIONAL M.N. | F29: VETERINARIA SAN PABLO E.I.R.L. | G29: SALDO A FAVOR | I29: PEN | J29: -96.83 | L29: 96.83 | M29: -96.83 | O29: PEREIRA FUENTES, EIGLY YARITZA
A30: BCP01/2025/11770 | B30: BCP01/2025/11770 | C30: 46013 | E30: 1220001 ANTICIPOS CLIENTES NACIONAL M.N. | F30: IDROGO MEDINA JUAN CARLOS | G30: saldo a favor | I30: PEN | J30: -151.31 | L30: 151.31 | M30: -151.31 | O30: MONTERO VILCAS, JOSE GORGE
A31: BBVA1/2025/04024 | B31: BBVA1/2025/04024 | C31: 46010 | E31: 1220001 ANTICIPOS CLIENTES NACIONAL M.N. | F31: INVERSIONES PROAVET E.I.R.L. | G31: SALDO A FAVOR | I31: PEN | J31: -190.5 | L31: 190.5 | M31: -190.5 | O31: PEREIRA FUENTES, EIGLY YARITZA
A32: BCP01/2025/11310 | B32: BCP01/2025/11310 | C32: 46006 | E32: 1220001 ANTICIPOS CLIENTES NACIONAL M.N. | F32: AGUIVET S.A.C. | G32: SALDO A FAVOR | I32: PEN | J32: -6521.91 | L32: 6521.91 | M32: -6521.91 | O32: PEREIRA FUENTES, EIGLY YARITZA
A33: BBVA1/2025/03966 | B33: BBVA1/2025/03966 | C33: 46006 | E33: 1220001 ANTICIPOS CLIENTES NACIONAL M.N. | F33: VETERINARIA PIURA SOCIEDAD ANONIMA CERRADA | G33: SALDO A FAVOR | I33: PEN | J33: -10 | L33: 10 | M33: -10 | O33: PEREIRA FUENTES, EIGLY YARITZA
A34: BCP01/2025/11285 | B34: BCP01/2025/11285 | C34: 46003 | E34: 1220001 ANTICIPOS CLIENTES NACIONAL M.N. | F34: CASA DEL BUEN CRIADOR E.I.R.L. | G34: SALDO FT 3651 | I34: PEN | J34: -245.7 | L34: 245.7 | M34: -245.7 | O34: BARCENA BRAGA, KATTYA ADELAIDA
A35: BCP01/2025/11162 | B35: BCP01/2025/11162 | C35: 45996 | E35: 1220001 ANTICIPOS CLIENTES NACIONAL M.N. | F35: HOSPITAL VETERINARIO S.A.C. | G35: SALDO A FAVOR PE S10920 | I35: PEN | J35: -97.94 | L35: 97.94 | M35: -97.94 | O35: PEREIRA FUENTES, EIGLY YARITZA
A36: BCP01/2025/10319 | B36: BCP01/2025/10319 | C36: 45975 | E36: 1220001 ANTICIPOS CLIENTES NACIONAL M.N. | F36: AGRIVET E INVERSIONES S.A.C. | G36: SALDO A FAVOR | I36: PEN | J36: -723.27 | L36: 723.27 | M36: -723.27 | O36: PEREIRA FUENTES, EIGLY YARITZA
A37: BCP01/2025/10162 | B37: BCP01/2025/10162 | C37: 45972 | E37: 1220001 ANTICIPOS CLIENTES NACIONAL M.N. | F37: AGRO QUIMICA SILVA S.A.C. | G37: DE AGRO QUIMICA SILVA SALDO | I37: PEN | J37: -2466.47 | L37: 2466.47 | M37: -2466.47 | O37: BARCENA BRAGA, KATTYA ADELAIDA
A38: BCP01/2025/09744 | B38: BCP01/2025/09744 | C38: 45954 | E38: 1220001 ANTICIPOS CLIENTES NACIONAL M.N. | F38: DOG CAT E.I.R.L. | G38: saldo a favor | I38: PEN | J38: -4.27 | L38: 4.27 | M38: -4.27 | O38: MONTERO VILCAS, JOSE GORGE
A39: BCP01/2025/09677 | B39: BCP01/2025/09677 | C39: 45952 | E39: 1220001 ANTICIPOS CLIENTES NACIONAL M.N. | F39: AGRO QUIMICA SILVA S.A.C. | G39: Saldo pendiente: S/ 41.95 - TRAN.CTAS.TERC.BM SALDO A FAVOR | I39: PEN | J39: 41.95 | K39: 41.95 | M39: 41.95 | O39: PEREIRA FUENTES, EIGLY YARITZA
A40: BCP01/2025/09576 | B40: BCP01/2025/09576 | C40: 45947 | E40: 1220001 ANTICIPOS CLIENTES NACIONAL M.N. | F40: MISTER PET S.A.C. | G40: DE MISTER PET SAC - ABONO | I40: PEN | J40: -21.97 | L40: 21.97 | M40: -21.97 | O40: BARCENA BRAGA, KATTYA ADELAIDA
...

Sheet 122xx2
A1: Asiento contable | B1: Número | C1: Fecha | D1: Fecha de vencimiento | E1: Cuenta | F1: Socio | G1: Etiqueta | H1: Referencia | I1: Moneda | J1: Importe en moneda | K1: Debe | L1: Haber | M1: Saldo | N1: Conciliación | O1: Creado por
A2: 1220002 ANTICIPOS CLIENTES NACIONAL M.E. (4)
A3: IBK01/2025/01119 | B3: IBK01/2025/01119 | C3: 46097 | E3: 1220002 ANTICIPOS CLIENTES NACIONAL M.E. | F3: OLEA ESTRADA CESAR AUGUSTO | G3: ABONO COMPRA DE VEH. | I3: USD | J3: -8400 | L3: 29005.2 | M3: -29005.2 | N3: A151999 | O3: BARCENA BRAGA, KATTYA ADELAIDA
M5: =SUM(M3:M4) -> -29005.2

Sheet 122xx3
A1: Asiento contable | B1: Número | C1: Fecha | D1: Fecha de vencimiento | E1: Cuenta | F1: Socio | G1: Etiqueta | H1: Referencia | I1: Moneda | J1: Importe en moneda | K1: Debe | L1: Haber | M1: Saldo | N1: Conciliación | O1: Creado por
A2: 1220003 ANTICIPOS CLIENTES DEL EXTERIOR (442)
A3: BCP03/2025/00524 | B3: BCP03/2025/00524 | C3: 46106 | E3: 1220003 ANTICIPOS CLIENTES DEL EXTERIOR | F3: INVERSIONES MONTECO DE CARTAGO S.A. | G3: saldo a favor | I3: USD | J3: -3779.99 | L3: 13093.88 | M3: -13093.88 | O3: MONTERO VILCAS, JOSE GORGE
A4: BCP03/2025/00517 | B4: BCP03/2025/00517 | C4: 46098 | E4: 1220003 ANTICIPOS CLIENTES DEL EXTERIOR | F4: GANESHA AGROFARMA | G4: saldo a favor | I4: USD | J4: -28900 | L4: 99387.1 | M4: -99387.1 | O4: MONTERO VILCAS, JOSE GORGE
A5: BCP03/2025/00515 | B5: BCP03/2025/00515 | C5: 46098 | E5: 1220003 ANTICIPOS CLIENTES DEL EXTERIOR | F5: GANESHA AGROFARMA | G5: saldo a favor | I5: USD | J5: -36960 | L5: 127105.44 | M5: -127105.44 | O5: MONTERO VILCAS, JOSE GORGE
A6: BCP02/2025/02356 | B6: BCP02/2025/02356 | C6: 46098 | E6: 1220003 ANTICIPOS CLIENTES DEL EXTERIOR | F6: STICHTING ANIMAL HEALTH MISSION SURINAME (S.A.H.M.S) | G6: saldo a favor | I6: USD | J6: -9124.23 | L6: 31378.23 | M6: -31378.23 | O6: MONTERO VILCAS, JOSE GORGE
A7: PAPANT/2025/07168 (F F15-00000333) | B7: PAPANT/2025/07168 | C7: 46073 | D7: 46073 | E7: 1220003 ANTICIPOS CLIENTES DEL EXTERIOR | F7: ISV - INSUMOS Y SANIDAD VETERINARIA SRL | G7: Pago de cliente $ 45,381.50 - ISV - INSUMOS Y SANIDAD VETERINARIA SRL - 20/02/2026 | H7: F F15-00000333 | I7: USD | J7: 45381.5 | K7: 152754.13 | M7: 152754.13 | O7: MONTERO VILCAS, JOSE GORGE
A8: CAMBI/2026/02/0813 | B8: CAMBI/2026/02/0813 | C8: 46073 | E8: 1220003 ANTICIPOS CLIENTES DEL EXTERIOR | F8: ISV - INSUMOS Y SANIDAD VETERINARIA SRL | G8: Diferencia en tipo de cambio de moneda | I8: USD | L8: 191.35 | M8: -191.35 | O8: MONTERO VILCAS, JOSE GORGE
A9: CAMBI/2026/02/0812 | B9: CAMBI/2026/02/0812 | C9: 46073 | E9: 1220003 ANTICIPOS CLIENTES DEL EXTERIOR | F9: ISV - INSUMOS Y SANIDAD VETERINARIA SRL | G9: Diferencia en tipo de cambio de moneda | I9: USD | K9: 20 | M9: 20 | O9: MONTERO VILCAS, JOSE GORGE
A10: CAMBI/2026/02/0811 | B10: CAMBI/2026/02/0811 | C10: 46073 | E10: 1220003 ANTICIPOS CLIENTES DEL EXTERIOR | F10: ISV - INSUMOS Y SANIDAD VETERINARIA SRL | G10: Diferencia en tipo de cambio de moneda | I10: USD | L10: 140 | M10: -140 | O10: MONTERO VILCAS, JOSE GORGE
A11: CAMBI/2026/02/0810 | B11: CAMBI/2026/02/0810 | C11: 46073 | E11: 1220003 ANTICIPOS CLIENTES DEL EXTERIOR | F11: ISV - INSUMOS Y SANIDAD VETERINARIA SRL | G11: Diferencia en tipo de cambio de moneda | I11: USD | L11: 23.76 | M11: -23.76 | O11: MONTERO VILCAS, JOSE GORGE
A12: BCP03/2025/00495 | B12: BCP03/2025/00495 | C12: 46071 | E12: 1220003 ANTICIPOS CLIENTES DEL EXTERIOR | F12: ISV - INSUMOS Y SANIDAD VETERINARIA SRL | G12: saldo a favor | I12: USD | J12: -10744.36 | L12: 35972.12 | M12: -35972.12 | O12: MONTERO VILCAS, JOSE GORGE
A13: BCP03/2025/00489 | B13: BCP03/2025/00489 | C13: 46065 | E13: 1220003 ANTICIPOS CLIENTES DEL EXTERIOR | F13: MONTECO ANIMAL HEALTH S.A. DE C.V. | G13: saldo a favor | I13: USD | J13: -26.52 | L13: 89.18 | M13: -89.18 | N13: A150401 | O13: MONTERO VILCAS, JOSE GORGE
A14: BCP03/2025/00482 | B14: BCP03/2025/00482 | C14: 46059 | E14: 1220003 ANTICIPOS CLIENTES DEL EXTERIOR | F14: ISV - INSUMOS Y SANIDAD VETERINARIA SRL | G14: SALDO A FAVOR | I14: USD | J14: -10000 | L14: 33680 | M14: -33680 | O14: MONTERO VILCAS, JOSE GORGE
A15: BCP03/2025/00480 | B15: BCP03/2025/00480 | C15: 46059 | E15: 1220003 ANTICIPOS CLIENTES DEL EXTERIOR | F15: GANESHA AGROFARMA | G15: SALDO A AFAVOR | I15: USD | J15: -37500 | L15: 126300 | M15: -126300 | O15: MONTERO VILCAS, JOSE GORGE
A16: BCP03/2025/00476 | B16: BCP03/2025/00476 | C16: 46056 | E16: 1220003 ANTICIPOS CLIENTES DEL EXTERIOR | F16: QUALITY CO. FOR VET.MED. TRADE | G16: SALDO A FAVOR | I16: USD | J16: -23960 | L16: 80721.24 | M16: -80721.24 | O16: MONTERO VILCAS, JOSE GORGE
A17: BCP03/2025/00464 | B17: BCP03/2025/00464 | C17: 46051 | E17: 1220003 ANTICIPOS CLIENTES DEL EXTERIOR | F17: GANESHA AGROFARMA | G17: SALDO A FAVOR | I17: USD | J17: -38700 | L17: 129451.5 | M17: -129451.5 | O17: MONTERO VILCAS, JOSE GORGE
A18: BCP03/2025/00462 | B18: BCP03/2025/00462 | C18: 46051 | E18: 1220003 ANTICIPOS CLIENTES DEL EXTERIOR | F18: MINH HUNG AGRICULTURAL MATERIALS TRADING AND SERVICE CO., LTD. | G18: SALDO A FAVOR | I18: USD | J18: -49823.37 | L18: 166659.17 | M18: -166659.17 | O18: MONTERO VILCAS, JOSE GORGE
A19: BCP03/2025/00461 | B19: BCP03/2025/00461 | C19: 46051 | E19: 1220003 ANTICIPOS CLIENTES DEL EXTERIOR | F19: MINH HUNG AGRICULTURAL MATERIALS TRADING AND SERVICE CO., LTD. | G19: saldo a favor | I19: USD | J19: -69046.69 | L19: 230961.18 | M19: -230961.18 | O19: MONTERO VILCAS, JOSE GORGE
A20: BCP03/2025/00468 | B20: BCP03/2025/00468 | C20: 46050 | E20: 1220003 ANTICIPOS CLIENTES DEL EXTERIOR | F20: AL MASEELA PHARMACEUTICAL COMPANY W.L.L. | G20: saldo a favor | I20: USD | J20: -12070.36 | L20: 40459.84 | M20: -40459.84 | O20: MONTERO VILCAS, JOSE GORGE
A21: BCP03/2025/00466 | B21: BCP03/2025/00466 | C21: 46050 | E21: 1220003 ANTICIPOS CLIENTES DEL EXTERIOR | F21: ISV - INSUMOS Y SANIDAD VETERINARIA SRL | G21: saldo a favor | I21: USD | J21: -10000 | L21: 33520 | M21: -33520 | O21: MONTERO VILCAS, JOSE GORGE
A22: PAPANT/2025/06526 (F F15-00000321) | B22: PAPANT/2025/06526 | C22: 46044 | D22: 46044 | E22: 1220003 ANTICIPOS CLIENTES DEL EXTERIOR | F22: ISV - INSUMOS Y SANIDAD VETERINARIA SRL | G22: Pago de cliente $ 54,956.36 - ISV - INSUMOS Y SANIDAD VETERINARIA SRL - 22/01/2026 | H22: F F15-00000321 | I22: USD | J22: 54956.36 | K22: 184598.41 | M22: 184598.41 | O22: MONTERO VILCAS, JOSE GORGE
A23: CAMBI/2026/01/0711 | B23: CAMBI/2026/01/0711 | C23: 46044 | E23: 1220003 ANTICIPOS CLIENTES DEL EXTERIOR | F23: ISV - INSUMOS Y SANIDAD VETERINARIA SRL | G23: Diferencia en tipo de cambio de moneda | I23: USD | L23: 0.01 | M23: -0.01 | O23: MONTERO VILCAS, JOSE GORGE
A24: CAMBI/2026/01/0711 | B24: CAMBI/2026/01/0711 | C24: 46044 | E24: 1220003 ANTICIPOS CLIENTES DEL EXTERIOR | F24: ISV - INSUMOS Y SANIDAD VETERINARIA SRL | G24: Diferencia en tipo de cambio de moneda | I24: USD | K24: 2.98 | M24: 2.98 | O24: MONTERO VILCAS, JOSE GORGE
A25: CAMBI/2026/01/0710 | B25: CAMBI/2026/01/0710 | C25: 46044 | E25: 1220003 ANTICIPOS CLIENTES DEL EXTERIOR | F25: ISV - INSUMOS Y SANIDAD VETERINARIA SRL | G25: Diferencia en tipo de cambio de moneda | I25: USD | K25: 17.78 | M25: 17.78 | O25: MONTERO VILCAS, JOSE GORGE
A26: CAMBI/2026/01/0709 | B26: CAMBI/2026/01/0709 | C26: 46044 | E26: 1220003 ANTICIPOS CLIENTES DEL EXTERIOR | F26: ISV - INSUMOS Y SANIDAD VETERINARIA SRL | G26: Diferencia en tipo de cambio de moneda | I26: USD | K26: 183.21 | M26: 183.21 | O26: MONTERO VILCAS, JOSE GORGE
A27: CAMBI/2026/01/0708 | B27: CAMBI/2026/01/0708 | C27: 46044 | E27: 1220003 ANTICIPOS CLIENTES DEL EXTERIOR | F27: ISV - INSUMOS Y SANIDAD VETERINARIA SRL | G27: Diferencia en tipo de cambio de moneda | I27: USD | K27: 368.2 | M27: 368.2 | O27: MONTERO VILCAS, JOSE GORGE
A28: CAMBI/2026/01/0707 | B28: CAMBI/2026/01/0707 | C28: 46044 | E28: 1220003 ANTICIPOS CLIENTES DEL EXTERIOR | F28: ISV - INSUMOS Y SANIDAD VETERINARIA SRL | G28: Diferencia en tipo de cambio de moneda | I28: USD | K28: 159.43 | M28: 159.43 | O28: MONTERO VILCAS, JOSE GORGE
A29: BCP03/2025/00509 | B29: BCP03/2025/00509 | C29: 46044 | E29: 1220003 ANTICIPOS CLIENTES DEL EXTERIOR | F29: QUALITY CO. FOR VET.MED. TRADE | G29: saldo a favor | I29: USD | J29: -28195 | L29: 94707.01 | M29: -94707.01 | O29: MONTERO VILCAS, JOSE GORGE
A30: BCP03/2025/00447 | B30: BCP03/2025/00447 | C30: 46042 | E30: 1220003 ANTICIPOS CLIENTES DEL EXTERIOR | F30: ISV - INSUMOS Y SANIDAD VETERINARIA SRL | G30: saldo a favor | I30: USD | J30: -10000 | L30: 33660 | M30: -33660 | O30: MONTERO VILCAS, JOSE GORGE
A31: BCP03/2025/00438 | B31: BCP03/2025/00438 | C31: 46036 | E31: 1220003 ANTICIPOS CLIENTES DEL EXTERIOR | F31: ISV - INSUMOS Y SANIDAD VETERINARIA SRL | G31: saldo a favor | I31: USD | J31: -8887.25 | L31: 29870.05 | M31: -29870.05 | O31: MONTERO VILCAS, JOSE GORGE
A32: BCP03/2025/00436 | B32: BCP03/2025/00436 | C32: 46036 | E32: 1220003 ANTICIPOS CLIENTES DEL EXTERIOR | F32: ISV - INSUMOS Y SANIDAD VETERINARIA SRL | G32: Incoming payment From 8217725021, I.S.V. INSUMOS Y SANIDAD VETERINAR+ Reference 2026011400320299 | I32: USD | J32: -6241.3 | L32: 20977.01 | M32: -20977.01 | O32: MONTERO VILCAS, JOSE GORGE
A33: BCP02/2025/02041 | B33: BCP02/2025/02041 | C33: 46036 | E33: 1220003 ANTICIPOS CLIENTES DEL EXTERIOR | F33: DUGGAN VETERINARY | G33: saldo a favor | I33: USD | J33: -30159.08 | L33: 101364.67 | M33: -101364.67 | O33: MONTERO VILCAS, JOSE GORGE
A34: PAPANT/2025/06393 (F F15-00000295) | B34: PAPANT/2025/06393 | C34: 46021 | D34: 46021 | E34: 1220003 ANTICIPOS CLIENTES DEL EXTERIOR | F34: ARMSTRONG HEALTH CARE INC. | G34: Pago de cliente $ 47,562.04 - ARMSTRONG HEALTH CARE INC. - 30/12/2025 | H34: F F15-00000295 | I34: USD | J34: 47562.04 | K34: 160379.2 | M34: 160379.2 | O34: MONTERO VILCAS, JOSE GORGE
A35: CAMBI/2025/12/2043 | B35: CAMBI/2025/12/2043 | C35: 46021 | E35: 1220003 ANTICIPOS CLIENTES DEL EXTERIOR | F35: ARMSTRONG HEALTH CARE INC. | G35: Diferencia en tipo de cambio de moneda | I35: USD | K35: 2670.3 | M35: 2670.3 | O35: MONTERO VILCAS, JOSE GORGE
A36: CAMBI/2025/12/2042 | B36: CAMBI/2025/12/2042 | C36: 46021 | E36: 1220003 ANTICIPOS CLIENTES DEL EXTERIOR | F36: ARMSTRONG HEALTH CARE INC. | G36: Diferencia en tipo de cambio de moneda | I36: USD | K36: 3990.8 | M36: 3990.8 | O36: MONTERO VILCAS, JOSE GORGE
A37: CAMBI/2025/12/2041 | B37: CAMBI/2025/12/2041 | C37: 46021 | E37: 1220003 ANTICIPOS CLIENTES DEL EXTERIOR | F37: ARMSTRONG HEALTH CARE INC. | G37: Diferencia en tipo de cambio de moneda | I37: USD | K37: 161.81 | M37: 161.81 | O37: MONTERO VILCAS, JOSE GORGE
A38: BCP03/2025/00434 | B38: BCP03/2025/00434 | C38: 46020 | E38: 1220003 ANTICIPOS CLIENTES DEL EXTERIOR | F38: MINH HUNG AGRICULTURAL MATERIALS TRADING AND SERVICE CO., LTD. | G38: saldo a favor final al 13.01.26 | I38: USD | J38: -10620.85 | L38: 35781.66 | M38: -35781.66 | O38: MONTERO VILCAS, JOSE GORGE
A39: BCP02/2025/01941 | B39: BCP02/2025/01941 | C39: 46020 | E39: 1220003 ANTICIPOS CLIENTES DEL EXTERIOR | F39: AL FIAFY FOR VETERINARY CARE | G39: saldo a favor al dia 13.01 | I39: USD | J39: -36283.14 | L39: 122237.89 | M39: -122237.89 | O39: MONTERO VILCAS, JOSE GORGE
